<mujoco model="T1">
  <default>
    <default class="robot">
      <default class="motor">
        <joint />
        <motor />
      </default>
      <default class="visual">
        <geom material="visualgeom" contype="0" conaffinity="0" group="2" />
      </default>
      <default class="collision">
        <geom material="collision_material" condim="3" contype="0" conaffinity="1" priority="1" group="1" solref="0.005 1" solimp="0.99 0.999 1e-05" friction="1 0.01 0.01" />
      </default>
    </default>
  </default>

  <compiler angle="radian" />

  <asset>
    <material name="empty" rgba="0.4 0.4 0.4 0.3" />
    <material name="default_material" rgba="0.7 0.7 0.7 1" />
    <material name="collision_material" rgba="1.0 0.28 0.1 0.9" />
    <mesh name="Trunk.STL" file="meshes/Trunk.STL" />
    <mesh name="H1.STL" file="meshes/H1.STL" />
    <mesh name="H2.STL" file="meshes/H2.STL" />
    <mesh name="AL1.STL" file="meshes/AL1.STL" />
    <mesh name="AL2.STL" file="meshes/AL2.STL" />
    <mesh name="AL3.STL" file="meshes/AL3.STL" />
    <mesh name="left_hand_link.STL" file="meshes/left_hand_link.STL" />
    <mesh name="AR1.STL" file="meshes/AR1.STL" />
    <mesh name="AR2.STL" file="meshes/AR2.STL" />
    <mesh name="AR3.STL" file="meshes/AR3.STL" />
    <mesh name="right_hand_link.STL" file="meshes/right_hand_link.STL" />
    <mesh name="Waist.STL" file="meshes/Waist.STL" />
    <mesh name="Hip_Pitch_Left.STL" file="meshes/Hip_Pitch_Left.STL" />
    <mesh name="Hip_Roll_Left.STL" file="meshes/Hip_Roll_Left.STL" />
    <mesh name="Hip_Yaw_Left.STL" file="meshes/Hip_Yaw_Left.STL" />
    <mesh name="Shank_Left.STL" file="meshes/Shank_Left.STL" />
    <mesh name="Ankle_Cross_Left.STL" file="meshes/Ankle_Cross_Left.STL" />
    <mesh name="left_foot_link.STL" file="meshes/left_foot_link.STL" />
    <mesh name="Hip_Pitch_Right.STL" file="meshes/Hip_Pitch_Right.STL" />
    <mesh name="Hip_Roll_Right.STL" file="meshes/Hip_Roll_Right.STL" />
    <mesh name="Hip_Yaw_Right.STL" file="meshes/Hip_Yaw_Right.STL" />
    <mesh name="Shank_Right.STL" file="meshes/Shank_Right.STL" />
    <mesh name="Ankle_Cross_Right.STL" file="meshes/Ankle_Cross_Right.STL" />
    <mesh name="right_foot_link.STL" file="meshes/right_foot_link.STL" />
  </asset>

  <worldbody>
    <body name="Trunk" pos="0.00000000 0.00000000 0.67335400" quat="1 0 0 0" childclass="robot">
      <freejoint name="floating_base" />
      <geom name="Trunk_collision" pos="0.06 0 0.12" quat="1.0 0.0 0.0 0.0" type="box" size="0.075 0.1 0.15" class="collision" />
      <geom name="Trunk_visual" pos="0 0 0" quat="1.0 0.0 0.0 0.0" material="empty" type="mesh" mesh="Trunk.STL" class="visual" />
      <body name="H1" pos="0.0625 0 0.243" quat="1.0 0.0 0.0 0.0">
        <joint name="AAHead_yaw" type="hinge" ref="0.0" class="motor" range="-1.57 1.57" axis="0 0 1" />
        <inertial pos="-0.000508 -0.001403 0.057432" quat="1.0 0.0 0.0 0.0" mass="0.443910" diaginertia="0.000224 0.000241 0.00015" />
        <geom name="H1_visual" pos="0 0 0" quat="1.0 0.0 0.0 0.0" material="empty" type="mesh" mesh="H1.STL" class="visual" />
        <body name="H2" pos="0 0 0.06185" quat="1.0 0.0 0.0 0.0">
          <joint name="Head_pitch" type="hinge" ref="0.0" class="motor" range="-0.35 1.22" axis="0 1 0" />
          <inertial pos="0.007802 0.001262 0.098631" quat="1.0 0.0 0.0 0.0" mass="0.631019" diaginertia="0.002025 0.00192 0.001739" />
          <geom name="H2_collision" pos="0.01 0 0.11" quat="1.0 0.0 0.0 0.0" type="sphere" size="0.08" class="collision" />
          <geom name="H2_visual" pos="0 0 0" quat="1.0 0.0 0.0 0.0" material="empty" type="mesh" mesh="H2.STL" class="visual" />
        </body>
      </body>
      <body name="AL1" pos="0.0575 0.1063 0.219" quat="0.999999902951242 0.0 0.0004405649857479046 0.0">
        <joint name="Left_Shoulder_Pitch" type="hinge" ref="0.0" class="motor" range="-3.31 1.22" axis="0 1 0" />
        <inertial pos="-0.000677 0.044974 0.000000" quat="1.0 0.0 0.0 0.0" mass="0.53" diaginertia="0.001293 0.000293 0.001367" />
        <geom name="AL1_visual" pos="0 0 0" quat="1.0 0.0 0.0 0.0" material="empty" type="mesh" mesh="AL1.STL" class="visual" />
        <body name="AL2" pos="0 0.047 0" quat="1.0 0.0 0.0 0.0">
          <joint name="Left_Shoulder_Roll" type="hinge" ref="0.0" class="motor" range="-1.74 1.57" axis="1 0 0" />
          <inertial pos="0.003862 0.037976 0.000000" quat="1.0 0.0 0.0 0.0" mass="0.160" diaginertia="0.000345 0.000177 0.000401" />
          <geom name="AL2_visual" pos="0 0 0" quat="1.0 0.0 0.0 0.0" material="empty" type="mesh" mesh="AL2.STL" class="visual" />
          <body name="AL3" pos="0.00025 0.0605 0" quat="1.0 0.0 0.0 0.0">
            <joint name="Left_Elbow_Pitch" type="hinge" ref="0.0" class="motor" range="-2.27 2.27" axis="0 1 0" />
            <inertial pos="0.000000 0.085353 -0.000099" quat="1.0 0.0 0.0 0.0" mass="1.02" diaginertia="0.012869 0.000621 0.012798" />
            <geom name="AL3_collision" pos="0 0.05 0" quat="0.7071054825112363 0.7071080798594735 0.0 0.0" type="cylinder" size="0.03 0.075" class="collision" />
            <geom name="AL3_visual" pos="0 0 0" quat="1.0 0.0 0.0 0.0" material="empty" type="mesh" mesh="AL3.STL" class="visual" />
            <body name="left_hand_link" pos="0 0.1471 0" quat="1.0 0.0 0.0 0.0">
              <joint name="Left_Elbow_Yaw" type="hinge" ref="0.0" class="motor" range="-2.44 0" axis="0 0 1" />
              <inertial pos="-0.000108 0.109573 0.000591" quat="1.0 0.0 0.0 0.0" mass="0.327214390850251" diaginertia="0.008159 0.000215 0.008131" />
              <geom name="left_hand_link_collision" pos="0 0.13 0" quat="0.7071054825112363 0.7071080798594735 0.0 0.0" type="cylinder" size="0.03 0.0875" class="collision" />
              <geom name="left_hand_link_visual" pos="0 0 0" quat="1.0 0.0 0.0 0.0" material="empty" type="mesh" mesh="left_hand_link.STL" class="visual" />
            </body>
          </body>
        </body>
      </body>
      <body name="AR1" pos="0.0575 -0.1063 0.219" quat="0.999999902951242 0.0 0.0004405649857479046 0.0">
        <joint name="Right_Shoulder_Pitch" type="hinge" ref="0.0" class="motor" range="-3.31 1.22" axis="0 1 0" />
        <inertial pos="-0.000677 -0.044974 0.000000" quat="1.0 0.0 0.0 0.0" mass="0.53" diaginertia="0.001293 0.000293 0.001367" />
        <geom name="AR1_visual" pos="0 0 0" quat="1.0 0.0 0.0 0.0" material="empty" type="mesh" mesh="AR1.STL" class="visual" />
        <body name="AR2" pos="0 -0.047 0" quat="1.0 0.0 0.0 0.0">
          <joint name="Right_Shoulder_Roll" type="hinge" ref="0.0" class="motor" range="-1.57 1.74" axis="1 0 0" />
          <inertial pos="0.003862 -0.037976 0.000000" quat="1.0 0.0 0.0 0.0" mass="0.160" diaginertia="0.000345 0.000177 0.000401" />
          <geom name="AR2_visual" pos="0 0 0" quat="1.0 0.0 0.0 0.0" material="empty" type="mesh" mesh="AR2.STL" class="visual" />
          <body name="AR3" pos="0.00025 -0.0605 0" quat="1.0 0.0 0.0 0.0">
            <joint name="Right_Elbow_Pitch" type="hinge" ref="0.0" class="motor" range="-2.27 2.27" axis="0 1 0" />
            <inertial pos="0.000000 -0.085353 -0.000099" quat="1.0 0.0 0.0 0.0" mass="1.02" diaginertia="0.012869 0.000621 0.012798" />
            <geom name="AR3_collision" pos="0 -0.05 0" quat="0.7071054825112363 0.7071080798594735 0.0 0.0" type="cylinder" size="0.03 0.075" class="collision" />
            <geom name="AR3_visual" pos="0 0 0" quat="1.0 0.0 0.0 0.0" material="empty" type="mesh" mesh="AR3.STL" class="visual" />
            <body name="right_hand_link" pos="0 -0.1471 0" quat="1.0 0.0 0.0 0.0">
              <joint name="Right_Elbow_Yaw" type="hinge" ref="0.0" class="motor" range="0 2.44" axis="0 0 1" />
              <inertial pos="-0.000108 -0.109573 0.000591" quat="1.0 0.0 0.0 0.0" mass="0.327214390850251" diaginertia="0.008159 0.000215 0.008131" />
              <geom name="right_hand_link_collision" pos="0 -0.13 0" quat="0.7071054825112363 0.7071080798594735 0.0 0.0" type="cylinder" size="0.03 0.0875" class="collision" />
              <geom name="right_hand_link_visual" pos="0 0 0" quat="1.0 0.0 0.0 0.0" material="empty" type="mesh" mesh="right_hand_link.STL" class="visual" />
            </body>
          </body>
        </body>
      </body>
      <body name="Waist" pos="0.0625 0 -0.1155" quat="1.0 0.0 0.0 0.0">
        <joint name="Waist" type="hinge" ref="0.0" class="motor" range="-1.57 1.57" axis="0 0 1" />
        <inertial pos="0.002284 0.000003 0.007301" quat="1.0 0.0 0.0 0.0" mass="2.581" diaginertia="0.005289 0.005299 0.004821" />
        <geom name="Waist_visual" pos="0 0 0" quat="1.0 0.0 0.0 0.0" material="empty" type="mesh" mesh="Waist.STL" class="visual" />
        <body name="Hip_Pitch_Left" pos="0 0.106 0" quat="1.0 0.0 0.0 0.0">
          <joint name="Left_Hip_Pitch" type="hinge" ref="0.0" class="motor" range="-1.8 1.57" axis="0 1 0" />
          <inertial pos="0.000534 -0.007296 -0.018083" quat="1.0 0.0 0.0 0.0" mass="1.021" diaginertia="0.001805 0.001421 0.001292" />
          <geom name="Hip_Pitch_Left_visual" pos="0 0 0" quat="1.0 0.0 0.0 0.0" material="empty" type="mesh" mesh="Hip_Pitch_Left.STL" class="visual" />
          <body name="Hip_Roll_Left" pos="0 0 -0.02" quat="1.0 0.0 0.0 0.0">
            <joint name="Left_Hip_Roll" type="hinge" ref="0.0" class="motor" range="-0.2 1.57" axis="1 0 0" />
            <inertial pos="0.001101 0.000024 -0.053750" quat="1.0 0.0 0.0 0.0" mass="0.385" diaginertia="0.001517 0.001743 0.000515" />
            <geom name="Hip_Roll_Left_collision" pos="0 0 -0.08" quat="1.0 0.0 0.0 0.0" type="cylinder" size="0.05 0.08" class="collision" />
            <geom name="Hip_Roll_Left_visual" pos="0 0 0" quat="1.0 0.0 0.0 0.0" material="empty" type="mesh" mesh="Hip_Roll_Left.STL" class="visual" />
            <body name="Hip_Yaw_Left" pos="0 0 -0.081854" quat="1.0 0.0 0.0 0.0">
              <joint name="Left_Hip_Yaw" type="hinge" ref="0.0" class="motor" range="-1 1" axis="0 0 1" />
              <inertial pos="-0.007233 0.000206 -0.089184" quat="1.0 0.0 0.0 0.0" mass="2.166" diaginertia="0.025108 0.025733 0.002787" />
              <geom name="Hip_Yaw_Left_visual" pos="0 0 0" quat="1.0 0.0 0.0 0.0" material="empty" type="mesh" mesh="Hip_Yaw_Left.STL" class="visual" />
              <body name="Shank_Left" pos="-0.014 0 -0.134" quat="1.0 0.0 0.0 0.0">
                <joint name="Left_Knee_Pitch" type="hinge" ref="0.0" class="motor" range="0 2.34" axis="0 1 0" />
                <inertial pos="-0.006012 0.000259 -0.124318" quat="1.0 0.0 0.0 0.0" mass="1.73" diaginertia="0.034618 0.034539 0.001934" />
                <geom name="Shank_Left_collision" pos="0 0 -0.12" quat="1.0 0.0 0.0 0.0" type="cylinder" size="0.05 0.075" class="collision" />
                <geom name="Shank_Left_visual" pos="0 0 0" quat="1.0 0.0 0.0 0.0" material="empty" type="mesh" mesh="Shank_Left.STL" class="visual" />
                <body name="Ankle_Cross_Left" pos="0 0 -0.28" quat="1.0 0.0 0.0 0.0">
                  <joint name="Left_Ankle_Pitch" type="hinge" ref="0.0" class="motor" range="-0.87 0.35" axis="0 1 0" />
                  <inertial pos="-0.003722 0.000000 -0.007981" quat="1.0 0.0 0.0 0.0" mass="0.073" diaginertia="1.2e-05 2.9e-05 2.5e-05" />
                  <geom name="Ankle_Cross_Left_visual" pos="0 0 0" quat="1.0 0.0 0.0 0.0" material="empty" type="mesh" mesh="Ankle_Cross_Left.STL" class="visual" />
                  <body name="left_foot_link" pos="0 0.00025 -0.012" quat="1.0 0.0 0.0 0.0">
                    <joint name="Left_Ankle_Roll" type="hinge" ref="0.0" class="motor" range="-0.44 0.44" axis="1 0 0" />
                    <inertial pos="-0.000249 0.000000 -0.009140" quat="1.0 0.0 0.0 0.0" mass="0.685" diaginertia="0.000738 0.002385 0.002671" />
                    <geom name="left_foot_link_collision" pos="0.01 0 -0.015" quat="1.0 0.0 0.0 0.0" type="box" size="0.1115 0.05 0.015" class="collision" />
                    <geom name="left_foot_link_visual" pos="0 0 0" quat="1.0 0.0 0.0 0.0" material="empty" type="mesh" mesh="left_foot_link.STL" class="visual" />
                  </body>
                </body>
              </body>
            </body>
          </body>
        </body>
        <body name="Hip_Pitch_Right" pos="0 -0.106 0" quat="1.0 0.0 0.0 0.0">
          <joint name="Right_Hip_Pitch" type="hinge" ref="0.0" class="motor" range="-1.8 1.57" axis="0 1 0" />
          <inertial pos="0.000534 0.007514 -0.018082" quat="1.0 0.0 0.0 0.0" mass="1.021" diaginertia="0.001805 0.001421 0.001292" />
          <geom name="Hip_Pitch_Right_visual" pos="0 0 0" quat="1.0 0.0 0.0 0.0" material="empty" type="mesh" mesh="Hip_Pitch_Right.STL" class="visual" />
          <body name="Hip_Roll_Right" pos="0 0 -0.02" quat="1.0 0.0 0.0 0.0">
            <joint name="Right_Hip_Roll" type="hinge" ref="0.0" class="motor" range="-1.57 0.2" axis="1 0 0" />
            <inertial pos="0.001099 0.000024 -0.053748" quat="1.0 0.0 0.0 0.0" mass="0.385" diaginertia="0.001517 0.001743 0.000515" />
            <geom name="Hip_Roll_Right_collision" pos="0 0 -0.08" quat="1.0 0.0 0.0 0.0" type="cylinder" size="0.05 0.08" class="collision" />
            <geom name="Hip_Roll_Right_visual" pos="0 0 0" quat="1.0 0.0 0.0 0.0" material="empty" type="mesh" mesh="Hip_Roll_Right.STL" class="visual" />
            <body name="Hip_Yaw_Right" pos="0 0 -0.081854" quat="1.0 0.0 0.0 0.0">
              <joint name="Right_Hip_Yaw" type="hinge" ref="0.0" class="motor" range="-1 1" axis="0 0 1" />
              <inertial pos="-0.007191 -0.000149 -0.089220" quat="1.0 0.0 0.0 0.0" mass="2.17" diaginertia="0.025137 0.025762 0.002787" />
              <geom name="Hip_Yaw_Right_visual" pos="0 0 0" quat="1.0 0.0 0.0 0.0" material="empty" type="mesh" mesh="Hip_Yaw_Right.STL" class="visual" />
              <body name="Shank_Right" pos="-0.014 0 -0.134" quat="1.0 0.0 0.0 0.0">
                <joint name="Right_Knee_Pitch" type="hinge" ref="0.0" class="motor" range="0 2.34" axis="0 1 0" />
                <inertial pos="-0.005741 -0.000541 -0.122602" quat="1.0 0.0 0.0 0.0" mass="1.79" diaginertia="0.035098 0.034958 0.002039" />
                <geom name="Shank_Right_collision" pos="0 0 -0.12" quat="1.0 0.0 0.0 0.0" type="cylinder" size="0.05 0.075" class="collision" />
                <geom name="Shank_Right_visual" pos="0 0 0" quat="1.0 0.0 0.0 0.0" material="empty" type="mesh" mesh="Shank_Right.STL" class="visual" />
                <body name="Ankle_Cross_Right" pos="0 0 -0.28" quat="1.0 0.0 0.0 0.0">
                  <joint name="Right_Ankle_Pitch" type="hinge" ref="0.0" class="motor" range="-0.87 0.35" axis="0 1 0" />
                  <inertial pos="-0.003722 0.000000 -0.007981" quat="1.0 0.0 0.0 0.0" mass="0.073" diaginertia="1.2e-05 2.9e-05 2.5e-05" />
                  <geom name="Ankle_Cross_Right_visual" pos="0 0 0" quat="1.0 0.0 0.0 0.0" material="empty" type="mesh" mesh="Ankle_Cross_Right.STL" class="visual" />
                  <body name="right_foot_link" pos="0 -0.00025 -0.012" quat="1.0 0.0 0.0 0.0">
                    <joint name="Right_Ankle_Roll" type="hinge" ref="0.0" class="motor" range="-0.44 0.44" axis="1 0 0" />
                    <inertial pos="-0.000248 0.000000 -0.009140" quat="1.0 0.0 0.0 0.0" mass="0.685" diaginertia="0.000738 0.002385 0.002671" />
                    <geom name="right_foot_link_collision" pos="0.01 0 -0.015" quat="1.0 0.0 0.0 0.0" type="box" size="0.1115 0.05 0.015" class="collision" />
                    <geom name="right_foot_link_visual" pos="0 0 0" quat="1.0 0.0 0.0 0.0" material="empty" type="mesh" mesh="right_foot_link.STL" class="visual" />
                  </body>
                </body>
              </body>
            </body>
          </body>
        </body>
      </body>
      <site name="Trunk_site" pos="0 0 0" quat="1 0 0 0" />
      <camera name="front_camera" mode="track" fovy="90.0" quat="4.329780281177467e-17 4.329780281177466e-17 0.7071067811865475 0.7071067811865476" pos="0.0 2.0 0.5" />
      <camera name="side_camera" mode="track" fovy="90.0" quat="-0.5 -0.4999999999999999 0.5 0.5000000000000001" pos="-2.0 0.0 0.5" />
    </body>
  </worldbody>

  <actuator>
    <motor name="AAHead_yaw_ctrl" joint="AAHead_yaw" class="motor" />
    <motor name="Head_pitch_ctrl" joint="Head_pitch" class="motor" />
    <motor name="Left_Shoulder_Pitch_ctrl" joint="Left_Shoulder_Pitch" class="motor" />
    <motor name="Left_Shoulder_Roll_ctrl" joint="Left_Shoulder_Roll" class="motor" />
    <motor name="Left_Elbow_Pitch_ctrl" joint="Left_Elbow_Pitch" class="motor" />
    <motor name="Left_Elbow_Yaw_ctrl" joint="Left_Elbow_Yaw" class="motor" />
    <motor name="Right_Shoulder_Pitch_ctrl" joint="Right_Shoulder_Pitch" class="motor" />
    <motor name="Right_Shoulder_Roll_ctrl" joint="Right_Shoulder_Roll" class="motor" />
    <motor name="Right_Elbow_Pitch_ctrl" joint="Right_Elbow_Pitch" class="motor" />
    <motor name="Right_Elbow_Yaw_ctrl" joint="Right_Elbow_Yaw" class="motor" />
    <motor name="Waist_ctrl" joint="Waist" class="motor" />
    <motor name="Left_Hip_Pitch_ctrl" joint="Left_Hip_Pitch" class="motor" />
    <motor name="Left_Hip_Roll_ctrl" joint="Left_Hip_Roll" class="motor" />
    <motor name="Left_Hip_Yaw_ctrl" joint="Left_Hip_Yaw" class="motor" />
    <motor name="Left_Knee_Pitch_ctrl" joint="Left_Knee_Pitch" class="motor" />
    <motor name="Left_Ankle_Pitch_ctrl" joint="Left_Ankle_Pitch" class="motor" />
    <motor name="Left_Ankle_Roll_ctrl" joint="Left_Ankle_Roll" class="motor" />
    <motor name="Right_Hip_Pitch_ctrl" joint="Right_Hip_Pitch" class="motor" />
    <motor name="Right_Hip_Roll_ctrl" joint="Right_Hip_Roll" class="motor" />
    <motor name="Right_Hip_Yaw_ctrl" joint="Right_Hip_Yaw" class="motor" />
    <motor name="Right_Knee_Pitch_ctrl" joint="Right_Knee_Pitch" class="motor" />
    <motor name="Right_Ankle_Pitch_ctrl" joint="Right_Ankle_Pitch" class="motor" />
    <motor name="Right_Ankle_Roll_ctrl" joint="Right_Ankle_Roll" class="motor" />
  </actuator>

  <contact>
    <exclude body1="AL3" body2="left_hand_link" />
    <exclude body1="AR3" body2="right_hand_link" />
  </contact>

  <sensor>
    <framepos name="Trunk_site_pos" objtype="site" objname="Trunk_site" />
    <framequat name="Trunk_site_quat" objtype="site" objname="Trunk_site" />
    <framelinvel name="Trunk_site_linvel" objtype="site" objname="Trunk_site" />
    <frameangvel name="Trunk_site_angvel" objtype="site" objname="Trunk_site" />
    <velocimeter name="Trunk_site_vel" site="Trunk_site" />
  </sensor>
</mujoco>